2023-12-09 15:46:15,834 - app - ERROR - Exception on /login [POST]
Traceback (most recent call last):
  File "C:\Users\kevina\AppData\Roaming\Python\Python311\site-packages\sqlalchemy\engine\base.py", line 1965, in _exec_single_context
    self.dialect.do_execute(
  File "C:\Users\kevina\AppData\Roaming\Python\Python311\site-packages\sqlalchemy\engine\default.py", line 921, in do_execute
    cursor.execute(statement, parameters)
psycopg2.errors.UndefinedColumn: column user.is_admin does not exist
LINE 1: ...mail, "user".password_hash AS user_password_hash, "user".is_...
                                                             ^


The above exception was the direct cause of the following exception:

Traceback (most recent call last):
  File "C:\Python311\Lib\site-packages\flask\app.py", line 2190, in wsgi_app
    response = self.full_dispatch_request()
               ^^^^^^^^^^^^^^^^^^^^^^^^^^^^
  File "C:\Python311\Lib\site-packages\flask\app.py", line 1486, in full_dispatch_request
    rv = self.handle_user_exception(e)
         ^^^^^^^^^^^^^^^^^^^^^^^^^^^^^
  File "C:\Python311\Lib\site-packages\flask_cors\extension.py", line 176, in wrapped_function
    return cors_after_request(app.make_response(f(*args, **kwargs)))
                                                ^^^^^^^^^^^^^^^^^^
  File "C:\Python311\Lib\site-packages\flask\app.py", line 1484, in full_dispatch_request
    rv = self.dispatch_request()
         ^^^^^^^^^^^^^^^^^^^^^^^
  File "C:\Python311\Lib\site-packages\flask\app.py", line 1469, in dispatch_request
    return self.ensure_sync(self.view_functions[rule.endpoint])(**view_args)
           ^^^^^^^^^^^^^^^^^^^^^^^^^^^^^^^^^^^^^^^^^^^^^^^^^^^^^^^^^^^^^^^^^
  File "C:\Users\kevina\Documents\~LLMS and AI\chatbot\auth.py", line 36, in login
    user = User.query.filter_by(username=username).first()
           ^^^^^^^^^^^^^^^^^^^^^^^^^^^^^^^^^^^^^^^^^^^^^^^
  File "C:\Users\kevina\AppData\Roaming\Python\Python311\site-packages\sqlalchemy\orm\query.py", line 2747, in first
    return self.limit(1)._iter().first()  # type: ignore
           ^^^^^^^^^^^^^^^^^^^^^
  File "C:\Users\kevina\AppData\Roaming\Python\Python311\site-packages\sqlalchemy\orm\query.py", line 2846, in _iter
    result: Union[ScalarResult[_T], Result[_T]] = self.session.execute(
                                                  ^^^^^^^^^^^^^^^^^^^^^
  File "C:\Users\kevina\AppData\Roaming\Python\Python311\site-packages\sqlalchemy\orm\session.py", line 2246, in execute
    return self._execute_internal(
           ^^^^^^^^^^^^^^^^^^^^^^^
  File "C:\Users\kevina\AppData\Roaming\Python\Python311\site-packages\sqlalchemy\orm\session.py", line 2141, in _execute_internal
    result: Result[Any] = compile_state_cls.orm_execute_statement(
                          ^^^^^^^^^^^^^^^^^^^^^^^^^^^^^^^^^^^^^^^^
  File "C:\Users\kevina\AppData\Roaming\Python\Python311\site-packages\sqlalchemy\orm\context.py", line 293, in orm_execute_statement
    result = conn.execute(
             ^^^^^^^^^^^^^
  File "C:\Users\kevina\AppData\Roaming\Python\Python311\site-packages\sqlalchemy\engine\base.py", line 1412, in execute
    return meth(
           ^^^^^
  File "C:\Users\kevina\AppData\Roaming\Python\Python311\site-packages\sqlalchemy\sql\elements.py", line 483, in _execute_on_connection
    return connection._execute_clauseelement(
           ^^^^^^^^^^^^^^^^^^^^^^^^^^^^^^^^^^
  File "C:\Users\kevina\AppData\Roaming\Python\Python311\site-packages\sqlalchemy\engine\base.py", line 1635, in _execute_clauseelement
    ret = self._execute_context(
          ^^^^^^^^^^^^^^^^^^^^^^
  File "C:\Users\kevina\AppData\Roaming\Python\Python311\site-packages\sqlalchemy\engine\base.py", line 1844, in _execute_context
    return self._exec_single_context(
           ^^^^^^^^^^^^^^^^^^^^^^^^^^
  File "C:\Users\kevina\AppData\Roaming\Python\Python311\site-packages\sqlalchemy\engine\base.py", line 1984, in _exec_single_context
    self._handle_dbapi_exception(
  File "C:\Users\kevina\AppData\Roaming\Python\Python311\site-packages\sqlalchemy\engine\base.py", line 2339, in _handle_dbapi_exception
    raise sqlalchemy_exception.with_traceback(exc_info[2]) from e
  File "C:\Users\kevina\AppData\Roaming\Python\Python311\site-packages\sqlalchemy\engine\base.py", line 1965, in _exec_single_context
    self.dialect.do_execute(
  File "C:\Users\kevina\AppData\Roaming\Python\Python311\site-packages\sqlalchemy\engine\default.py", line 921, in do_execute
    cursor.execute(statement, parameters)
sqlalchemy.exc.ProgrammingError: (psycopg2.errors.UndefinedColumn) column user.is_admin does not exist
LINE 1: ...mail, "user".password_hash AS user_password_hash, "user".is_...
                                                             ^

[SQL: SELECT "user".id AS user_id, "user".username AS user_username, "user".email AS user_email, "user".password_hash AS user_password_hash, "user".is_admin AS user_is_admin, "user".status AS user_status, "user".created_at AS user_created_at, "user".updated_at AS user_updated_at, "user".last_login AS user_last_login 
FROM "user" 
WHERE "user".username = %(username_1)s 
 LIMIT %(param_1)s]
[parameters: {'username_1': 'kevina', 'param_1': 1}]
(Background on this error at: https://sqlalche.me/e/20/f405)
